<?xml version="1.0"?>
<robot xmlns:xacro="http://ros.org/wiki/xacro" name="mobile_manipulator">

  <!-- Materials -->
  <material name="Grey"><color rgba="0.5 0.5 0.5 1"/></material>
  <material name="Black"><color rgba="0 0 0 1"/></material>
  <material name="Blue"><color rgba="0 0 1 1"/></material>

  <!-- Base Link -->
  <link name="base_link">
    <visual>
      <geometry><box size="0.7 0.5 0.2"/></geometry>
      <material name="Grey"/>
    </visual>
    <collision>
      <geometry><box size="0.7 0.5 0.2"/></geometry>
    </collision>
    <inertial>
      <mass value="6.0"/>
      <inertia ixx="0.1" ixy="0" ixz="0" iyy="0.1" iyz="0" izz="0.1"/>
    </inertial>
  </link>

  <!-- Back Electronics Box -->
  <link name="back_box">
    <visual>
      <geometry><box size="0.2 0.3 0.15"/></geometry>
      <origin xyz="-0.35 0 0.175" rpy="0 0 0"/>
      <material name="Grey"/>
    </visual>
    <collision>
      <geometry><box size="0.2 0.3 0.15"/></geometry>
      <origin xyz="-0.35 0 0.175" rpy="0 0 0"/>
    </collision>
    <inertial>
      <mass value="1.0"/>
      <inertia ixx="0.01" ixy="0" ixz="0" iyy="0.01" iyz="0" izz="0.01"/>
    </inertial>
  </link>

  <joint name="back_box_joint" type="fixed">
    <parent link="base_link"/>
    <child link="back_box"/>
    <origin xyz="0 0 0" rpy="0 0 0"/>
  </joint>

  <!-- Wheel Macro -->
  <xacro:macro name="wheel" params="name x y">
    <link name="${name}_wheel_link">
      <visual>
        <geometry><cylinder radius="0.15" length="0.08"/></geometry>
        <origin xyz="0 0 0" rpy="1.5708 0 0"/>
        <material name="Black"/>
      </visual>
      <collision>
        <geometry><cylinder radius="0.15" length="0.08"/></geometry>
        <origin xyz="0 0 0" rpy="1.5708 0 0"/>
      </collision>
      <inertial>
        <mass value="1.0"/>
        <inertia ixx="0.01" ixy="0" ixz="0" iyy="0.01" iyz="0" izz="0.01"/>
      </inertial>
    </link>
    <joint name="${name}_wheel_joint" type="continuous">
      <parent link="base_link"/>
      <child link="${name}_wheel_link"/>
      <origin xyz="${x} ${y} -0.1" rpy="0 0 0"/>
      <axis xyz="0 1 0"/>
    </joint>
  </xacro:macro>

  <!-- Instantiate Wheels -->
  <xacro:wheel name="front_left"  x="0.3" y=" 0.25"/>
  <xacro:wheel name="front_right" x="0.3" y="-0.25"/>
  <xacro:wheel name="rear_left"   x="-0.3" y=" 0.25"/>
  <xacro:wheel name="rear_right"  x="-0.3" y="-0.25"/>

  <!-- Arm Link 1 (Shoulder) -->
  <link name="arm_link_1">
    <visual>
      <geometry><cylinder length="0.2" radius="0.03"/></geometry>
      <origin xyz="0 0 0.1" rpy="0 1.5708 0"/>
      <material name="Blue"/>
    </visual>
    <collision>
      <geometry><cylinder length="0.2" radius="0.03"/></geometry>
      <origin xyz="0 0 0.1" rpy="0 1.5708 0"/>
    </collision>
    <inertial>
      <mass value="0.5"/>
      <inertia ixx="0.001" ixy="0" ixz="0" iyy="0.001" iyz="0" izz="0.001"/>
    </inertial>
  </link>
  <joint name="arm_base_joint" type="revolute">
    <parent link="base_link"/>
    <child link="arm_link_1"/>
    <origin xyz="0 0 0.1" rpy="0 0 0"/>
    <axis xyz="0 0 1"/>
    <limit lower="-1.57" upper="1.57" effort="1" velocity="1"/>
  </joint>

  <!-- Arm Link 2 (Elbow) -->
  <link name="arm_link_2">
    <visual>
      <geometry><cylinder length="0.2" radius="0.025"/></geometry>
      <origin xyz="0 0 0.1" rpy="0 1.5708 0"/>
      <material name="Blue"/>
    </visual>
    <collision>
      <geometry><cylinder length="0.2" radius="0.025"/></geometry>
      <origin xyz="0 0 0.1" rpy="0 1.5708 0"/>
    </collision>
    <inertial>
      <mass value="0.3"/>
      <inertia ixx="0.001" ixy="0" ixz="0" iyy="0.001" iyz="0" izz="0.001"/>
    </inertial>
  </link>
  <joint name="arm_elbow_joint" type="revolute">
    <parent link="arm_link_1"/>
    <child link="arm_link_2"/>
    <origin xyz="0 0 0.2" rpy="0 0 0"/>
    <axis xyz="0 1 0"/>
    <limit lower="-1.57" upper="1.57" effort="1" velocity="1"/>
  </joint>

  <!-- Arm Link 3 (Wrist) -->
  <link name="arm_link_3">
    <visual>
      <geometry><cylinder length="0.15" radius="0.02"/></geometry>
      <origin xyz="0 0 0.075" rpy="0 1.5708 0"/>
      <material name="Blue"/>
    </visual>
    <collision>
      <geometry><cylinder length="0.15" radius="0.02"/></geometry>
      <origin xyz="0 0 0.075" rpy="0 1.5708 0"/>
    </collision>
    <inertial>
      <mass value="0.2"/>
      <inertia ixx="0.0005" ixy="0" ixz="0" iyy="0.0005" iyz="0" izz="0.0005"/>
    </inertial>
  </link>
  <joint name="arm_wrist_joint" type="revolute">
    <parent link="arm_link_2"/>
    <child link="arm_link_3"/>
    <origin xyz="0 0 0.2" rpy="0 0 0"/>
    <axis xyz="0 1 0"/>
    <limit lower="-1.57" upper="1.57" effort="1" velocity="1"/>
  </joint>

  <!-- Simplified RG2 Gripper Box -->
  <link name="rg2_gripper">
    <visual>
      <geometry><box size="0.1 0.05 0.05"/></geometry>
      <origin xyz="0.05 0 0" rpy="0 0 0"/>
      <material name="Blue"/>
    </visual>
    <collision>
      <geometry><box size="0.1 0.05 0.05"/></geometry>
      <origin xyz="0.05 0 0" rpy="0 0 0"/>
    </collision>
    <inertial>
      <mass value="0.5"/>
      <inertia ixx="0.001" ixy="0" ixz="0" iyy="0.001" iyz="0" izz="0.001"/>
    </inertial>
  </link>
  <joint name="gripper_joint" type="fixed">
    <parent link="arm_link_3"/>
    <child link="rg2_gripper"/>
    <origin xyz="0 0 0.15" rpy="0 0 0"/>
  </joint>

  <!-- Gripper Fingers -->
  <link name="gripper_finger_left">
    <visual><geometry><cylinder radius="0.01" length="0.05"/></geometry>
           <origin xyz="0.1 0.015 0" rpy="1.5708 0 0"/><material name="Blue"/></visual>
  </link>
  <joint name="finger_left_joint" type="fixed">
    <parent link="rg2_gripper"/>
    <child link="gripper_finger_left"/>
    <origin xyz="0 0 0" rpy="0 0 0"/>
  </joint>

  <link name="gripper_finger_right">
    <visual><geometry><cylinder radius="0.01" length="0.05"/></geometry>
           <origin xyz="0.1 -0.015 0" rpy="1.5708 0 0"/><material name="Blue"/></visual>
  </link>
  <joint name="finger_right_joint" type="fixed">
    <parent link="rg2_gripper"/>
    <child link="gripper_finger_right"/>
    <origin xyz="0 0 0" rpy="0 0 0"/>
  </joint>

  <!-- Gazebo Diff Drive Plugin -->
  <gazebo>
    <plugin name="diff_drive_controller" filename="libgazebo_ros_diff_drive.so">
      <ros>
        <remapping>cmd_vel:=cmd_vel</remapping>
      </ros>
      <left_wheel>front_left_wheel_joint</left_wheel>
      <right_wheel>front_right_wheel_joint</right_wheel>
      <wheel_separation>0.5</wheel_separation>
      <wheel_diameter>0.3</wheel_diameter>
      <command_topic>cmd_vel</command_topic>
      <odometry_topic>odom</odometry_topic>
      <pose_covariance_diagonal>0.1 0.1 0.1 0.1 0.1 0.1</pose_covariance_diagonal>
    </plugin>
  </gazebo>

  <!-- Arm Controller Plugin (MoveIt) -->
  <controller name="arm_controller" type="position_controllers/JointTrajectoryController">
    <joint_names>
      <joint_name>arm_base_joint</joint_name>
      <joint_name>arm_elbow_joint</joint_name>
      <joint_name>arm_wrist_joint</joint_name>
    </joint_names>
  </controller>

</robot>
